
Beginning at: 2018-07-27 19:22:29.926589

Beginning at: 2018-07-27 19:22:34.710322

Beginning at: 2018-07-27 19:22:57.582239
Serving on ('127.0.0.1', 5000). Hit CTRL-C to stop.
GET http://port:9200/wiki/page/_search [status:N/A request:0.012s]
Traceback (most recent call last):
  File "/Users/nikneym/Documents/Projects/Woogle/microservice_elastic/venv/lib/python3.7/site-packages/urllib3/connection.py", line 171, in _new_conn
    (self._dns_host, self.port), self.timeout, **extra_kw)
  File "/Users/nikneym/Documents/Projects/Woogle/microservice_elastic/venv/lib/python3.7/site-packages/urllib3/util/connection.py", line 56, in create_connection
    for res in socket.getaddrinfo(host, port, family, socket.SOCK_STREAM):
  File "/Library/Frameworks/Python.framework/Versions/3.7/lib/python3.7/socket.py", line 748, in getaddrinfo
    for res in _socket.getaddrinfo(host, port, family, type, proto, flags):
socket.gaierror: [Errno 8] nodename nor servname provided, or not known

During handling of the above exception, another exception occurred:

Traceback (most recent call last):
  File "/Users/nikneym/Documents/Projects/Woogle/microservice_elastic/venv/lib/python3.7/site-packages/elasticsearch/connection/http_urllib3.py", line 171, in perform_request
    response = self.pool.urlopen(method, url, body, retries=False, headers=request_headers, **kw)
  File "/Users/nikneym/Documents/Projects/Woogle/microservice_elastic/venv/lib/python3.7/site-packages/urllib3/connectionpool.py", line 638, in urlopen
    _stacktrace=sys.exc_info()[2])
  File "/Users/nikneym/Documents/Projects/Woogle/microservice_elastic/venv/lib/python3.7/site-packages/urllib3/util/retry.py", line 343, in increment
    raise six.reraise(type(error), error, _stacktrace)
  File "/Users/nikneym/Documents/Projects/Woogle/microservice_elastic/venv/lib/python3.7/site-packages/urllib3/packages/six.py", line 686, in reraise
    raise value
  File "/Users/nikneym/Documents/Projects/Woogle/microservice_elastic/venv/lib/python3.7/site-packages/urllib3/connectionpool.py", line 600, in urlopen
    chunked=chunked)
  File "/Users/nikneym/Documents/Projects/Woogle/microservice_elastic/venv/lib/python3.7/site-packages/urllib3/connectionpool.py", line 354, in _make_request
    conn.request(method, url, **httplib_request_kw)
  File "/Library/Frameworks/Python.framework/Versions/3.7/lib/python3.7/http/client.py", line 1229, in request
    self._send_request(method, url, body, headers, encode_chunked)
  File "/Library/Frameworks/Python.framework/Versions/3.7/lib/python3.7/http/client.py", line 1275, in _send_request
    self.endheaders(body, encode_chunked=encode_chunked)
  File "/Library/Frameworks/Python.framework/Versions/3.7/lib/python3.7/http/client.py", line 1224, in endheaders
    self._send_output(message_body, encode_chunked=encode_chunked)
  File "/Library/Frameworks/Python.framework/Versions/3.7/lib/python3.7/http/client.py", line 1016, in _send_output
    self.send(msg)
  File "/Library/Frameworks/Python.framework/Versions/3.7/lib/python3.7/http/client.py", line 956, in send
    self.connect()
  File "/Users/nikneym/Documents/Projects/Woogle/microservice_elastic/venv/lib/python3.7/site-packages/urllib3/connection.py", line 196, in connect
    conn = self._new_conn()
  File "/Users/nikneym/Documents/Projects/Woogle/microservice_elastic/venv/lib/python3.7/site-packages/urllib3/connection.py", line 180, in _new_conn
    self, "Failed to establish a new connection: %s" % e)
urllib3.exceptions.NewConnectionError: <urllib3.connection.HTTPConnection object at 0x104f1b400>: Failed to establish a new connection: [Errno 8] nodename nor servname provided, or not known
Connection <Urllib3HttpConnection: http://port:9200> has failed for 1 times in a row, putting on 60 second timeout.
GET http://host:9200/wiki/page/_search [status:N/A request:10.020s]
Traceback (most recent call last):
  File "/Users/nikneym/Documents/Projects/Woogle/microservice_elastic/venv/lib/python3.7/site-packages/urllib3/connection.py", line 171, in _new_conn
    (self._dns_host, self.port), self.timeout, **extra_kw)
  File "/Users/nikneym/Documents/Projects/Woogle/microservice_elastic/venv/lib/python3.7/site-packages/urllib3/util/connection.py", line 79, in create_connection
    raise err
  File "/Users/nikneym/Documents/Projects/Woogle/microservice_elastic/venv/lib/python3.7/site-packages/urllib3/util/connection.py", line 69, in create_connection
    sock.connect(sa)
socket.timeout: timed out

During handling of the above exception, another exception occurred:

Traceback (most recent call last):
  File "/Users/nikneym/Documents/Projects/Woogle/microservice_elastic/venv/lib/python3.7/site-packages/elasticsearch/connection/http_urllib3.py", line 171, in perform_request
    response = self.pool.urlopen(method, url, body, retries=False, headers=request_headers, **kw)
  File "/Users/nikneym/Documents/Projects/Woogle/microservice_elastic/venv/lib/python3.7/site-packages/urllib3/connectionpool.py", line 638, in urlopen
    _stacktrace=sys.exc_info()[2])
  File "/Users/nikneym/Documents/Projects/Woogle/microservice_elastic/venv/lib/python3.7/site-packages/urllib3/util/retry.py", line 343, in increment
    raise six.reraise(type(error), error, _stacktrace)
  File "/Users/nikneym/Documents/Projects/Woogle/microservice_elastic/venv/lib/python3.7/site-packages/urllib3/packages/six.py", line 686, in reraise
    raise value
  File "/Users/nikneym/Documents/Projects/Woogle/microservice_elastic/venv/lib/python3.7/site-packages/urllib3/connectionpool.py", line 600, in urlopen
    chunked=chunked)
  File "/Users/nikneym/Documents/Projects/Woogle/microservice_elastic/venv/lib/python3.7/site-packages/urllib3/connectionpool.py", line 354, in _make_request
    conn.request(method, url, **httplib_request_kw)
  File "/Library/Frameworks/Python.framework/Versions/3.7/lib/python3.7/http/client.py", line 1229, in request
    self._send_request(method, url, body, headers, encode_chunked)
  File "/Library/Frameworks/Python.framework/Versions/3.7/lib/python3.7/http/client.py", line 1275, in _send_request
    self.endheaders(body, encode_chunked=encode_chunked)
  File "/Library/Frameworks/Python.framework/Versions/3.7/lib/python3.7/http/client.py", line 1224, in endheaders
    self._send_output(message_body, encode_chunked=encode_chunked)
  File "/Library/Frameworks/Python.framework/Versions/3.7/lib/python3.7/http/client.py", line 1016, in _send_output
    self.send(msg)
  File "/Library/Frameworks/Python.framework/Versions/3.7/lib/python3.7/http/client.py", line 956, in send
    self.connect()
  File "/Users/nikneym/Documents/Projects/Woogle/microservice_elastic/venv/lib/python3.7/site-packages/urllib3/connection.py", line 196, in connect
    conn = self._new_conn()
  File "/Users/nikneym/Documents/Projects/Woogle/microservice_elastic/venv/lib/python3.7/site-packages/urllib3/connection.py", line 176, in _new_conn
    (self.host, self.timeout))
urllib3.exceptions.ConnectTimeoutError: (<urllib3.connection.HTTPConnection object at 0x104f1b470>, 'Connection to host timed out. (connect timeout=10)')
Connection <Urllib3HttpConnection: http://host:9200> has failed for 1 times in a row, putting on 60 second timeout.
Resurrecting connection <Urllib3HttpConnection: http://port:9200> (force=True).
GET http://port:9200/wiki/page/_search [status:N/A request:0.002s]
Traceback (most recent call last):
  File "/Users/nikneym/Documents/Projects/Woogle/microservice_elastic/venv/lib/python3.7/site-packages/urllib3/connection.py", line 171, in _new_conn
    (self._dns_host, self.port), self.timeout, **extra_kw)
  File "/Users/nikneym/Documents/Projects/Woogle/microservice_elastic/venv/lib/python3.7/site-packages/urllib3/util/connection.py", line 56, in create_connection
    for res in socket.getaddrinfo(host, port, family, socket.SOCK_STREAM):
  File "/Library/Frameworks/Python.framework/Versions/3.7/lib/python3.7/socket.py", line 748, in getaddrinfo
    for res in _socket.getaddrinfo(host, port, family, type, proto, flags):
socket.gaierror: [Errno 8] nodename nor servname provided, or not known

During handling of the above exception, another exception occurred:

Traceback (most recent call last):
  File "/Users/nikneym/Documents/Projects/Woogle/microservice_elastic/venv/lib/python3.7/site-packages/elasticsearch/connection/http_urllib3.py", line 171, in perform_request
    response = self.pool.urlopen(method, url, body, retries=False, headers=request_headers, **kw)
  File "/Users/nikneym/Documents/Projects/Woogle/microservice_elastic/venv/lib/python3.7/site-packages/urllib3/connectionpool.py", line 638, in urlopen
    _stacktrace=sys.exc_info()[2])
  File "/Users/nikneym/Documents/Projects/Woogle/microservice_elastic/venv/lib/python3.7/site-packages/urllib3/util/retry.py", line 343, in increment
    raise six.reraise(type(error), error, _stacktrace)
  File "/Users/nikneym/Documents/Projects/Woogle/microservice_elastic/venv/lib/python3.7/site-packages/urllib3/packages/six.py", line 686, in reraise
    raise value
  File "/Users/nikneym/Documents/Projects/Woogle/microservice_elastic/venv/lib/python3.7/site-packages/urllib3/connectionpool.py", line 600, in urlopen
    chunked=chunked)
  File "/Users/nikneym/Documents/Projects/Woogle/microservice_elastic/venv/lib/python3.7/site-packages/urllib3/connectionpool.py", line 354, in _make_request
    conn.request(method, url, **httplib_request_kw)
  File "/Library/Frameworks/Python.framework/Versions/3.7/lib/python3.7/http/client.py", line 1229, in request
    self._send_request(method, url, body, headers, encode_chunked)
  File "/Library/Frameworks/Python.framework/Versions/3.7/lib/python3.7/http/client.py", line 1275, in _send_request
    self.endheaders(body, encode_chunked=encode_chunked)
  File "/Library/Frameworks/Python.framework/Versions/3.7/lib/python3.7/http/client.py", line 1224, in endheaders
    self._send_output(message_body, encode_chunked=encode_chunked)
  File "/Library/Frameworks/Python.framework/Versions/3.7/lib/python3.7/http/client.py", line 1016, in _send_output
    self.send(msg)
  File "/Library/Frameworks/Python.framework/Versions/3.7/lib/python3.7/http/client.py", line 956, in send
    self.connect()
  File "/Users/nikneym/Documents/Projects/Woogle/microservice_elastic/venv/lib/python3.7/site-packages/urllib3/connection.py", line 196, in connect
    conn = self._new_conn()
  File "/Users/nikneym/Documents/Projects/Woogle/microservice_elastic/venv/lib/python3.7/site-packages/urllib3/connection.py", line 180, in _new_conn
    self, "Failed to establish a new connection: %s" % e)
urllib3.exceptions.NewConnectionError: <urllib3.connection.HTTPConnection object at 0x104f1b550>: Failed to establish a new connection: [Errno 8] nodename nor servname provided, or not known
Connection <Urllib3HttpConnection: http://port:9200> has failed for 2 times in a row, putting on 120 second timeout.
Resurrecting connection <Urllib3HttpConnection: http://host:9200> (force=True).
GET http://host:9200/wiki/page/_search [status:N/A request:10.003s]
Traceback (most recent call last):
  File "/Users/nikneym/Documents/Projects/Woogle/microservice_elastic/venv/lib/python3.7/site-packages/urllib3/connection.py", line 171, in _new_conn
    (self._dns_host, self.port), self.timeout, **extra_kw)
  File "/Users/nikneym/Documents/Projects/Woogle/microservice_elastic/venv/lib/python3.7/site-packages/urllib3/util/connection.py", line 79, in create_connection
    raise err
  File "/Users/nikneym/Documents/Projects/Woogle/microservice_elastic/venv/lib/python3.7/site-packages/urllib3/util/connection.py", line 69, in create_connection
    sock.connect(sa)
socket.timeout: timed out

During handling of the above exception, another exception occurred:

Traceback (most recent call last):
  File "/Users/nikneym/Documents/Projects/Woogle/microservice_elastic/venv/lib/python3.7/site-packages/elasticsearch/connection/http_urllib3.py", line 171, in perform_request
    response = self.pool.urlopen(method, url, body, retries=False, headers=request_headers, **kw)
  File "/Users/nikneym/Documents/Projects/Woogle/microservice_elastic/venv/lib/python3.7/site-packages/urllib3/connectionpool.py", line 638, in urlopen
    _stacktrace=sys.exc_info()[2])
  File "/Users/nikneym/Documents/Projects/Woogle/microservice_elastic/venv/lib/python3.7/site-packages/urllib3/util/retry.py", line 343, in increment
    raise six.reraise(type(error), error, _stacktrace)
  File "/Users/nikneym/Documents/Projects/Woogle/microservice_elastic/venv/lib/python3.7/site-packages/urllib3/packages/six.py", line 686, in reraise
    raise value
  File "/Users/nikneym/Documents/Projects/Woogle/microservice_elastic/venv/lib/python3.7/site-packages/urllib3/connectionpool.py", line 600, in urlopen
    chunked=chunked)
  File "/Users/nikneym/Documents/Projects/Woogle/microservice_elastic/venv/lib/python3.7/site-packages/urllib3/connectionpool.py", line 354, in _make_request
    conn.request(method, url, **httplib_request_kw)
  File "/Library/Frameworks/Python.framework/Versions/3.7/lib/python3.7/http/client.py", line 1229, in request
    self._send_request(method, url, body, headers, encode_chunked)
  File "/Library/Frameworks/Python.framework/Versions/3.7/lib/python3.7/http/client.py", line 1275, in _send_request
    self.endheaders(body, encode_chunked=encode_chunked)
  File "/Library/Frameworks/Python.framework/Versions/3.7/lib/python3.7/http/client.py", line 1224, in endheaders
    self._send_output(message_body, encode_chunked=encode_chunked)
  File "/Library/Frameworks/Python.framework/Versions/3.7/lib/python3.7/http/client.py", line 1016, in _send_output
    self.send(msg)
  File "/Library/Frameworks/Python.framework/Versions/3.7/lib/python3.7/http/client.py", line 956, in send
    self.connect()
  File "/Users/nikneym/Documents/Projects/Woogle/microservice_elastic/venv/lib/python3.7/site-packages/urllib3/connection.py", line 196, in connect
    conn = self._new_conn()
  File "/Users/nikneym/Documents/Projects/Woogle/microservice_elastic/venv/lib/python3.7/site-packages/urllib3/connection.py", line 176, in _new_conn
    (self.host, self.timeout))
urllib3.exceptions.ConnectTimeoutError: (<urllib3.connection.HTTPConnection object at 0x10537e128>, 'Connection to host timed out. (connect timeout=10)')
Connection <Urllib3HttpConnection: http://host:9200> has failed for 2 times in a row, putting on 120 second timeout.
127.0.0.1 [27/Jul/2018:16:23:06 +0000] "GET /?index=wiki&doc_type=page&search=Australia HTTP/1.0" 500 482 "-" "ApacheBench/2.3"
Resurrecting connection <Urllib3HttpConnection: http://port:9200> (force=True).
GET http://port:9200/wiki/page/_search [status:N/A request:0.002s]
Traceback (most recent call last):
  File "/Users/nikneym/Documents/Projects/Woogle/microservice_elastic/venv/lib/python3.7/site-packages/urllib3/connection.py", line 171, in _new_conn
    (self._dns_host, self.port), self.timeout, **extra_kw)
  File "/Users/nikneym/Documents/Projects/Woogle/microservice_elastic/venv/lib/python3.7/site-packages/urllib3/util/connection.py", line 56, in create_connection
    for res in socket.getaddrinfo(host, port, family, socket.SOCK_STREAM):
  File "/Library/Frameworks/Python.framework/Versions/3.7/lib/python3.7/socket.py", line 748, in getaddrinfo
    for res in _socket.getaddrinfo(host, port, family, type, proto, flags):
socket.gaierror: [Errno 8] nodename nor servname provided, or not known

During handling of the above exception, another exception occurred:

Traceback (most recent call last):
  File "/Users/nikneym/Documents/Projects/Woogle/microservice_elastic/venv/lib/python3.7/site-packages/elasticsearch/connection/http_urllib3.py", line 171, in perform_request
    response = self.pool.urlopen(method, url, body, retries=False, headers=request_headers, **kw)
  File "/Users/nikneym/Documents/Projects/Woogle/microservice_elastic/venv/lib/python3.7/site-packages/urllib3/connectionpool.py", line 638, in urlopen
    _stacktrace=sys.exc_info()[2])
  File "/Users/nikneym/Documents/Projects/Woogle/microservice_elastic/venv/lib/python3.7/site-packages/urllib3/util/retry.py", line 343, in increment
    raise six.reraise(type(error), error, _stacktrace)
  File "/Users/nikneym/Documents/Projects/Woogle/microservice_elastic/venv/lib/python3.7/site-packages/urllib3/packages/six.py", line 686, in reraise
    raise value
  File "/Users/nikneym/Documents/Projects/Woogle/microservice_elastic/venv/lib/python3.7/site-packages/urllib3/connectionpool.py", line 600, in urlopen
    chunked=chunked)
  File "/Users/nikneym/Documents/Projects/Woogle/microservice_elastic/venv/lib/python3.7/site-packages/urllib3/connectionpool.py", line 354, in _make_request
    conn.request(method, url, **httplib_request_kw)
  File "/Library/Frameworks/Python.framework/Versions/3.7/lib/python3.7/http/client.py", line 1229, in request
    self._send_request(method, url, body, headers, encode_chunked)
  File "/Library/Frameworks/Python.framework/Versions/3.7/lib/python3.7/http/client.py", line 1275, in _send_request
    self.endheaders(body, encode_chunked=encode_chunked)
  File "/Library/Frameworks/Python.framework/Versions/3.7/lib/python3.7/http/client.py", line 1224, in endheaders
    self._send_output(message_body, encode_chunked=encode_chunked)
  File "/Library/Frameworks/Python.framework/Versions/3.7/lib/python3.7/http/client.py", line 1016, in _send_output
    self.send(msg)
  File "/Library/Frameworks/Python.framework/Versions/3.7/lib/python3.7/http/client.py", line 956, in send
    self.connect()
  File "/Users/nikneym/Documents/Projects/Woogle/microservice_elastic/venv/lib/python3.7/site-packages/urllib3/connection.py", line 196, in connect
    conn = self._new_conn()
  File "/Users/nikneym/Documents/Projects/Woogle/microservice_elastic/venv/lib/python3.7/site-packages/urllib3/connection.py", line 180, in _new_conn
    self, "Failed to establish a new connection: %s" % e)
urllib3.exceptions.NewConnectionError: <urllib3.connection.HTTPConnection object at 0x10537e7b8>: Failed to establish a new connection: [Errno 8] nodename nor servname provided, or not known
Connection <Urllib3HttpConnection: http://port:9200> has failed for 3 times in a row, putting on 240 second timeout.
Resurrecting connection <Urllib3HttpConnection: http://host:9200> (force=True).
GET http://host:9200/wiki/page/_search [status:N/A request:10.002s]
Traceback (most recent call last):
  File "/Users/nikneym/Documents/Projects/Woogle/microservice_elastic/venv/lib/python3.7/site-packages/urllib3/connection.py", line 171, in _new_conn
    (self._dns_host, self.port), self.timeout, **extra_kw)
  File "/Users/nikneym/Documents/Projects/Woogle/microservice_elastic/venv/lib/python3.7/site-packages/urllib3/util/connection.py", line 79, in create_connection
    raise err
  File "/Users/nikneym/Documents/Projects/Woogle/microservice_elastic/venv/lib/python3.7/site-packages/urllib3/util/connection.py", line 69, in create_connection
    sock.connect(sa)
socket.timeout: timed out

During handling of the above exception, another exception occurred:

Traceback (most recent call last):
  File "/Users/nikneym/Documents/Projects/Woogle/microservice_elastic/venv/lib/python3.7/site-packages/elasticsearch/connection/http_urllib3.py", line 171, in perform_request
    response = self.pool.urlopen(method, url, body, retries=False, headers=request_headers, **kw)
  File "/Users/nikneym/Documents/Projects/Woogle/microservice_elastic/venv/lib/python3.7/site-packages/urllib3/connectionpool.py", line 638, in urlopen
    _stacktrace=sys.exc_info()[2])
  File "/Users/nikneym/Documents/Projects/Woogle/microservice_elastic/venv/lib/python3.7/site-packages/urllib3/util/retry.py", line 343, in increment
    raise six.reraise(type(error), error, _stacktrace)
  File "/Users/nikneym/Documents/Projects/Woogle/microservice_elastic/venv/lib/python3.7/site-packages/urllib3/packages/six.py", line 686, in reraise
    raise value
  File "/Users/nikneym/Documents/Projects/Woogle/microservice_elastic/venv/lib/python3.7/site-packages/urllib3/connectionpool.py", line 600, in urlopen
    chunked=chunked)
  File "/Users/nikneym/Documents/Projects/Woogle/microservice_elastic/venv/lib/python3.7/site-packages/urllib3/connectionpool.py", line 354, in _make_request
    conn.request(method, url, **httplib_request_kw)
  File "/Library/Frameworks/Python.framework/Versions/3.7/lib/python3.7/http/client.py", line 1229, in request
    self._send_request(method, url, body, headers, encode_chunked)
  File "/Library/Frameworks/Python.framework/Versions/3.7/lib/python3.7/http/client.py", line 1275, in _send_request
    self.endheaders(body, encode_chunked=encode_chunked)
  File "/Library/Frameworks/Python.framework/Versions/3.7/lib/python3.7/http/client.py", line 1224, in endheaders
    self._send_output(message_body, encode_chunked=encode_chunked)
  File "/Library/Frameworks/Python.framework/Versions/3.7/lib/python3.7/http/client.py", line 1016, in _send_output
    self.send(msg)
  File "/Library/Frameworks/Python.framework/Versions/3.7/lib/python3.7/http/client.py", line 956, in send
    self.connect()
  File "/Users/nikneym/Documents/Projects/Woogle/microservice_elastic/venv/lib/python3.7/site-packages/urllib3/connection.py", line 196, in connect
    conn = self._new_conn()
  File "/Users/nikneym/Documents/Projects/Woogle/microservice_elastic/venv/lib/python3.7/site-packages/urllib3/connection.py", line 176, in _new_conn
    (self.host, self.timeout))
urllib3.exceptions.ConnectTimeoutError: (<urllib3.connection.HTTPConnection object at 0x10537ee48>, 'Connection to host timed out. (connect timeout=10)')
Connection <Urllib3HttpConnection: http://host:9200> has failed for 3 times in a row, putting on 240 second timeout.
Resurrecting connection <Urllib3HttpConnection: http://port:9200> (force=True).
GET http://port:9200/wiki/page/_search [status:N/A request:0.003s]
Traceback (most recent call last):
  File "/Users/nikneym/Documents/Projects/Woogle/microservice_elastic/venv/lib/python3.7/site-packages/urllib3/connection.py", line 171, in _new_conn
    (self._dns_host, self.port), self.timeout, **extra_kw)
  File "/Users/nikneym/Documents/Projects/Woogle/microservice_elastic/venv/lib/python3.7/site-packages/urllib3/util/connection.py", line 56, in create_connection
    for res in socket.getaddrinfo(host, port, family, socket.SOCK_STREAM):
  File "/Library/Frameworks/Python.framework/Versions/3.7/lib/python3.7/socket.py", line 748, in getaddrinfo
    for res in _socket.getaddrinfo(host, port, family, type, proto, flags):
socket.gaierror: [Errno 8] nodename nor servname provided, or not known

During handling of the above exception, another exception occurred:

Traceback (most recent call last):
  File "/Users/nikneym/Documents/Projects/Woogle/microservice_elastic/venv/lib/python3.7/site-packages/elasticsearch/connection/http_urllib3.py", line 171, in perform_request
    response = self.pool.urlopen(method, url, body, retries=False, headers=request_headers, **kw)
  File "/Users/nikneym/Documents/Projects/Woogle/microservice_elastic/venv/lib/python3.7/site-packages/urllib3/connectionpool.py", line 638, in urlopen
    _stacktrace=sys.exc_info()[2])
  File "/Users/nikneym/Documents/Projects/Woogle/microservice_elastic/venv/lib/python3.7/site-packages/urllib3/util/retry.py", line 343, in increment
    raise six.reraise(type(error), error, _stacktrace)
  File "/Users/nikneym/Documents/Projects/Woogle/microservice_elastic/venv/lib/python3.7/site-packages/urllib3/packages/six.py", line 686, in reraise
    raise value
  File "/Users/nikneym/Documents/Projects/Woogle/microservice_elastic/venv/lib/python3.7/site-packages/urllib3/connectionpool.py", line 600, in urlopen
    chunked=chunked)
  File "/Users/nikneym/Documents/Projects/Woogle/microservice_elastic/venv/lib/python3.7/site-packages/urllib3/connectionpool.py", line 354, in _make_request
    conn.request(method, url, **httplib_request_kw)
  File "/Library/Frameworks/Python.framework/Versions/3.7/lib/python3.7/http/client.py", line 1229, in request
    self._send_request(method, url, body, headers, encode_chunked)
  File "/Library/Frameworks/Python.framework/Versions/3.7/lib/python3.7/http/client.py", line 1275, in _send_request
    self.endheaders(body, encode_chunked=encode_chunked)
  File "/Library/Frameworks/Python.framework/Versions/3.7/lib/python3.7/http/client.py", line 1224, in endheaders
    self._send_output(message_body, encode_chunked=encode_chunked)
  File "/Library/Frameworks/Python.framework/Versions/3.7/lib/python3.7/http/client.py", line 1016, in _send_output
    self.send(msg)
  File "/Library/Frameworks/Python.framework/Versions/3.7/lib/python3.7/http/client.py", line 956, in send
    self.connect()
  File "/Users/nikneym/Documents/Projects/Woogle/microservice_elastic/venv/lib/python3.7/site-packages/urllib3/connection.py", line 196, in connect
    conn = self._new_conn()
  File "/Users/nikneym/Documents/Projects/Woogle/microservice_elastic/venv/lib/python3.7/site-packages/urllib3/connection.py", line 180, in _new_conn
    self, "Failed to establish a new connection: %s" % e)
urllib3.exceptions.NewConnectionError: <urllib3.connection.HTTPConnection object at 0x10537ef60>: Failed to establish a new connection: [Errno 8] nodename nor servname provided, or not known
Connection <Urllib3HttpConnection: http://port:9200> has failed for 4 times in a row, putting on 480 second timeout.
Resurrecting connection <Urllib3HttpConnection: http://host:9200> (force=True).
Task was destroyed but it is pending!
task: <Task pending coro=<RequestHandler.start() running at /Users/nikneym/Documents/Projects/Woogle/microservice_elastic/venv/lib/python3.7/site-packages/aiohttp/web_protocol.py:361> wait_for=<Future pending cb=[<TaskWakeupMethWrapper object at 0x10316ec78>()]>>
Task was destroyed but it is pending!
task: <Task pending coro=<RequestHandler.start() done, defined at /Users/nikneym/Documents/Projects/Woogle/microservice_elastic/venv/lib/python3.7/site-packages/aiohttp/web_protocol.py:342> wait_for=<Future pending cb=[<TaskWakeupMethWrapper object at 0x10339aee8>()]>>
